Workbook
Name Svar: [1]Blad1!$A$1:$A$2
Name Svar10: [2]Blad1!$A$1:$A$2
Name Svar11: [2]Blad1!$A$5:$A$7

Sheet 1. Leverantörsinformation
A4: 13.1 Anbudsformulär - Ekalunds Industriområde Dnr:2023-0285
A6: Datum 2025-04-08
A8: Leverantörsinformation | B8: (De vita fälten fylls i av anbudsgivaren)
A10: 1. Anbudsgivare | B10: Information
A11: Leverantörsnamn
A12: Organisationsnummer
A13: Kontaktperson för anbudet
A14: Telefonnummer
A15: Mailadress
A16: Behörig företrädare för anbudet (om annan än kontaktpersonen)
A17: Telefonnummer
A18: Mailadress

Sheet 2. Organisation
A4: 13.1 Anbudsformulär - Ekalunds Industriområde Dnr:2023-0285
A6: ='1. Leverantörsinformation'!A6 -> Datum 2025-04-08
A8: Uppgifter entreprenörsorganisation | B8: (De vita fälten fylls i av anbudsgivaren)
A10: Entreprenörens Nyckelroller (Grupp 1)
A11: Roll | B11: Namn | C11: Telefonnummer | D11: Mailadress
A12: Platschef | E12: CV ska bifogas enligt handling 9.1 punkt AFB.623
A13: Arbetsledare | E13: CV ska bifogas enligt handling 9.1 punkt AFB.623
A15: Entreprenörens Övriga roller
A16: Roll | B16: Namn | C16: Telefonnummer | D16: Mailadress
A17: Ombud
A18: Arbetschef
A19: Geotekniker
A20: Miljöansvarig
A21: Kvalitetsansvarig
A22: Byggarbetsmiljösamordnare BAS-U | E22: Utbildning och erfarenhet styrks vid startmöte, AFD.1833.

Sheet 3. Extern kapacitet
A4: 13.1 Anbudsformulär - Ekalunds Industriområde Dnr:2023-0285
A6: ='1. Leverantörsinformation'!A6 -> Datum 2025-04-08
A8: Extern kapacitet
A10: Instruktioner: Nedan kan du som Anbudsgivare ange om du vill åberopa annat företags kapacitet för att uppfylla krav som avser ekonomisk och finansiell ställning eller teknisk och yrkesmässig kapacitet, se punkt AFB.624 "Åberopa extern kapacitet" i de administrativa föreskrifterna. För de fall annat företags kapacitet åberopas bör du som Anbudsgivare bifoga ett samarbetsavtal/garantiförbindelse till anbudet som styrker att ni kommer att förfoga över de nödvändiga resurserna när kontraktet ska fullgöras. Ett sådant samarbetsavtal/garantiförbindelse kan exempelvis avse ett moderbolagsintyg, undertecknat av moderbolagets firmatecknare, som bevisar att kravet om ekonomisk stabilitet är uppfyllt. Ange i så fall bilagans namn under flik 5 "Krav" rad 39.
A23: Extern kapacitet, om sådan åberopas. (Vitfärgade rutor fylls i av anbudsgivaren OM kapacitet åberopas) | E23: Extern kapacitet, om sådan åberopas. (Vitfärgade rutor fylls i av anbudsgivaren OM kapacitet åberopas)
A24: Leverantörsnamn | E24: Leverantörsnamn
A25: Organisationsnummer | E25: Organisationsnummer
A26: Adress | E26: Adress
A27: Postnummer, Ort | E27: Postnummer, Ort
A28: Kontaktperson | E28: Kontaktperson
A29: Telefonnummer | E29: Telefonnummer
A30: Mailadress | E30: Mailadress
A31: Vilket åtagande åberopas företaget för? (Skriv i fritextfältet nedan) | E31: Vilket åtagande åberopas företaget för? (Skriv i fritextfältet nedan)
A40: Extern kapacitet, om sådan åberopas. (Vitfärgade rutor fylls i av anbudsgivaren OM kapacitet åberopas) | E40: Extern kapacitet, om sådan åberopas. (Vitfärgade rutor fylls i av anbudsgivaren OM kapacitet åberopas)
A41: Leverantörsnamn | E41: Leverantörsnamn
A42: Organisationsnummer | E42: Organisationsnummer
... A48: Vilket åtagande åberopas företaget för? (Skriv i fritextfältet nedan) | E48: Vilket åtagande åberopas företaget för? (Skriv i fritextfältet nedan)

Sheet 4. Referenser
A4: 13.1 Anbudsformulär - Ekalunds Industriområde Dnr:2023-0285
A6: ='1. Leverantörsinformation'!A6 -> Datum 2025-04-08
A8: Referenser | D8: (De vita fälten fylls i av anbudsgivaren)
A10: Instruktioner: Fyll i uppgifter för åberopade referensuppdrag nedan. Var noga med att de uppfyller ställda krav i AFB.623 under rubriken "Referenser".
A13: Referensuppdrag Anbudsgivare | D13: Uppgifter | H13: Referensuppdrag Platschef | K13: Uppgifter
A14: Referensuppdrag | H14: Referensuppdrag
A15: Namn på beställande företag | H15: Namn på beställande företag
A16: Namn på kontaktperson | H16: Namn på kontaktperson
A17: Befattning på kontaktperson | H17: Befattning på kontaktperson
A18: Telenr till kontaktperson | H18: Telenr till kontaktperson
A19: E-post till kontaktperson | H19: E-post till kontaktperson
A20: Kontraktsstart | H20: Kontraktsstart
A21: Kontraktsslut | H21: Kontraktsslut
A22: Kontraktssumma | H22: Kontraktssumma
A23: Kortfattad beskrivning av uppdraget | H23: Kortfattad beskrivning av uppdraget
A26: Referensuppdrag Arbetsledare | D26: Uppgifter
A27: Referensuppdrag
A28: Namn på beställande företag
A29: Namn på kontaktperson
A30: Befattning på kontaktperson
A31: Telenr till kontaktperson
A32: E-post till kontaktperson
A33: Kontraktsstart
A34: Kontraktsslut
A35: Kontraktssumma
A36: Kortfattad beskrivning av uppdraget

Sheet 5. Krav
A4: 13.1 Anbudsformulär - Ekalunds Industriområde Dnr:2023-0285
A6: ='1. Leverantörsinformation'!A6 -> Datum 2025-04-08
A8: Krav på anbud och anbudsgivare | D8: (vita fält fylls i av anbudsgivaren)
A10: Instruktioner: Nedan kan du som leverantör stämma av att du uppfyller de formella kraven, kvalificeringskraven samt de obligatoriska kraven i upphandlingen, vilket krävs för att anbudet ska gå vidare till utvärdering. Observera att det föreligger andra obligatoriska krav i underlaget som inte är nödvändiga att uppfylla vid anbudslämnande utan först under avtalstiden. Dessa accepteras genom att du som Anbudsgivare svarar JA på rad 45 i denna flik.
A16: Förklaring av färgkoder i svarsrutorna (färgmarkering sker per automatik när du väljer ditt svar i rullistan)
A17: Ja | C17: Krav är uppfyllt
A18: Nej | C18: Krav är inte uppfyllt vilket innebär att anbudet förkastas
A19: Ej aktuellt | C19: Förfrågan ej aktuell, innebär inte att anbudet förkastas
A21: Anbudsgivning | E21: Rullista i denna kolumn
A22: Uteslutning av leverantör
A23: Uteslutningsgrunder | E23: Kravet Uppfylls? | F23: Bilaga nr/namn:
A24: Anbudsgivaren intygar att det inte föreligger grund för uteslutning enligt AFB.61, för det egna företaget, genom inlämnadne av anbud. | F24: Ange bilagans namn
A25: Anbudsgivaren intygar att det inte föreligger grund för uteslutning för eventuell underleverantör som åberopas för att uppfylla något av kraven avseende ekonomisk och finansiell ställning eller teknisk och yrkesmässig kapacitet, se punkt AFB.61 i de administrativa föreskrifterna. Anbudsgivaren intygar detta genom inlämnande av anbud (endast om annans kapacitet åberopas). | F25: Ange bilagans namn (endast om annans kapacitet åberopas).
A26: Uppgifter från skatte- och kronofogdemyndigheten | E26: Kravet Uppfylls? | F26: Bilaga nr/namn:
A27: Anbudsgivaren intygar att det egna företaget och eventuella underleverantörer uppfyller lagenligt ställda krav avseende skatt- och avgiftsskyldighet i enlighet med punkt AFB.621 i de administrativa föreskrifterna. | F27: Krävs ingen bilaga!
A28: Prövning av leverantörs lämplighet
A29: Registrering | E29: Kravet Uppfylls?
A30: Anbudsgivaren intygar att det egna företaget och eventuella underleverantörer uppfyller ställda krav avseende registrering i enlighet med punkt AFB.621 "Behörighet att utöva yrkesverksamhet" i de administrativa föreskrifterna. | F30: Krävs ingen bilaga!
A31: Ekonomisk ställning | E31: Kravet Uppfylls? | F31: Bilaga nr/namn:
A32: Anbudsgivaren intygar att de uppnår en rating i enlighet med punkt AFB.622 "Krav på ekonomisk ställning" i de administrativa föreskrifterna. Om anbudsgivaren inte uppfyller kraven i AFB.622 så bereds anbudsgivaren möjlighet att styrka att kravet uppfylls på annat vis genom att bifoga en bilaga till anbudet som styrker detta. Ange bilagans namn till höger i det vita fältet. | F32: Ange bilagans namn (endast om Anbudsgivaren vill åberopa annat bevis än Creditsafe)
A33: Anbydsgivare intygar att det uppfyller ställda krav avseende omsättning under de senaste avslutade räkenskapsåret? | F33: Ange bilagans namn (endast om Anbudsgivaren vill åberopa annat bevis än Creditsafe)
A34: Teknisk och yrkesmässig kapacitet | E34: Kravet Uppfylls? | F34: Bilaga nr/namn:
A35: Anbudsgivaren uppfyller krav på referenser i enlighet med villkoren i punkt AFB.623 p. A samt B "Referenser" i de administrativa föreskrifterna? | F35: Anges direkt i anbudsformuläret, flik 4.
A36: Anbudsgivaren har bifogat CV för offererad platschef i enlighet med villkoren i AFB.623 p.B "Organisaton" i de administrativa föreskrifterna? | F36: Ange bilagans namn
A37: Anbudsgivaren har bifogat CV för offererad arbetsledare i enlighet med villkoren i AFB.623 p.B "Organisatione" i de administrativa föreskrifterna? | F37: Ange bilagans namn
A38: Anbudsgivaren uppfyller kraven gällande BAS-U i AFC.1833? | F38: Styrks i samband med startmöte.
A39: Anbudsgivaren har bifogat bevis på att denne kommer att förfoga över annans kapacitet i enlighet med villkoren i punkt AFB.624 "Åberopa extern kapacitet" i de administrativa föreskrifterna (endast om annans kapacitet åberopas)? | F39: Ange bilagans namn (endast om annans kapacitet åberopas)
A40: Anbudsgivaren har ett kvalitetsledningssystem i enlighet med punkt AFC.2211 i de administrativa föreskrifterna? | F40: Ange bilagans namn (Frivilligt att bifoga, styrks senast vid startmöte)
A41: Anbudsgivaren har ett miljöledningssystem i enlighet med punkt AFC.2212 i de administrativa föreskrifterna? | F41: Ange bilagans namn (Frivilligt att bifoga, styrks senast vid startmöte)
A42: Anbudsgivaren har en allrisk- och ansvarsförsäkring (samt övriga försäkringar som krävs) som uppfyller krav enligt AFC.54 samt underpnkter i de administrativa föreskrifterna? | F42: Försäkringsbevis uppvisas inför signeringa av uppdragsbeställning.
A43: Övriga villkor | F43: Bilaga nr/namn:
A44: Föreligger sekretessbegäran i enlighet med villkoren i punkt AFB.65 i de administrativa föreskrifterna? Om ja, ange bilagans namn till höger i det vita fältet. | F44: Ange bilagans namn (endast om anbudsgivaren begär sekretess)
A45: Samtliga villkor i de administrativa föreskrifterna och övriga handlingar i upphandlingsdokument accepteras? | F45: Krävs ingen bilaga!

Sheet Handling 10.1 Mändförteckning M
A1: #VALUE! | C1: DOKUMENT | D1: STATUS | H1: Instruktion: Samtliga gråa fält fylls i av anbudsgivaren. Negativ prissättning acceoteras ej, se AFB.41 i upphandlingens administrativa föreskrifter (AF).
C2: 10.1 MÄNGDFÖRTECKNING MED BESKRIVNING | D2: Förfrågningsunderlag
C3: PROJEKT | D3: DOKUMENTNUMMER
C4: Ekalund exploatering | D4: 10.1
D5: DATUM | F5: BET. | G5: SIDA
D6: 2025-02-13
A7: HANDLÄGGARE | B7: UPPDRAGSNUMMER | C7: INNEHÅLL | D7: ÄNDRINGSDATUM | F7: TOTAL ANBUDSSUMMA MF10.1
A8: HL | B8: 20000520 | F8: =SUM(G10:G2619) -> 0
A9: KOD | C9: TEXT | D9: ENHET | E9: MÄNGD | F9: À-PRIS | G9: BELOPP
C11: Denna tekniska beskrivning ansluter till AMA Anläggning 23
A13: B | C13: FÖRARBETEN, HJÄLPARBETEN, SANERINGSARBETEN, FLYTTNING, DEMONTERING, RIVNING, RÖJNING M M
C14: Vid arbeten som utföra i och i anslutning till arbetsområdet ska skyddsåtgärder vidtas och försiktighetsmått vidtas för att förebygga och hindra eller motverka att markvatten, grundvatten och ytvatten förorenas eller på annat sätt påverkas så att skada eller olägenhet kan uppkomma för människors, djurs eller naturens hälsa och miljö. Entreprenören har skyldighet att skaffa sig den kännedom om arbetsområdet och övriga förhållanden kräver och som kan påverka anbudet, genom okulärbesiktning.
A16: BB | C16: FÖRARBETEN
A18: BBB | C18: UTFÖRDA UNDERSÖKNINGAR O D
A20: BBB.1 | C20: Mark- och vattenförhållanden, förutsättningar för dimensionering m m
C21: Rapport avseende de marktekniska undersökningarna redovisas i handling 13.2 MUR_Eka 3_3 och Eka 3_6 mfl samt 13.3 PM Geoteknik_Eka 3_3 & 3_6 mfl.
A23: BBB.11 | C23: Mark- och vattenförhållanden m m
A25: BBB.111 | C25: Topografiska förhållanden
C26: Befintliga förhållanden framgår av ritningar Z-51.1-2001 - Z-97.1-2028. Se BBB.1 för utförda undersökningar
A28: BBB.112 | C28: Jordmåns- och vegetationsförhållanden
C29: Befintliga förhållanden framgår av ritningar Z-51.1-2001 - Z-97.1-2028. Se BBB.1 för utförda undersökningar.
C31: I dagsläget består undersökningsområdet av skogsmark, urskog och odlingsytor. Se ritningar Z-51.1-2001 - Z-97.1-2028 samt tillhörande MUR (13.2 MUR_Eka 3_3 och Eka 3_6 mfl).
C33: området är avverkat under 2023 och inom området förekommer ris samt stubbar ifrån denna avverkning
A35: BBB.113 | C35: Geotekniska förhållanden
C36: Se BBB.1 för utförda undersökningar.
C38: Området består utav tidigare åker samt skogsmark.
A40: BBB.1131 | C40: Geotekniska förhållanden i jord
C41: Generellt i nu utförda undersökningar utgörs marken, under ett lager av mullhaltig sand, alternativt av sandmorän ner till undersökt djup. Mullhaltig sand Markytan inom undersökningsområdet utgörs huvudsakligen av mullhaltig sand eller sandig mulljord med en mäktighet på ca 0,1–0,5 m. I undersökningspunkt C06 påträffades ett torvlager under 0,2 m sandig mulljord, med utbredning ner till ca 0,6 m u my. Sand/grusig sand Under den mullhaltiga sanden förekommer sand eller grusig sand i områdets nordöstra och sydöstra delar, med en mäktighet på ca 1,0–2,0 m. Hejarsonderingar indikerar en friktionsvinkel på ca 36° och en E-modul på ca 25 MPa. Lagret har en medelfast till fast lagringstäthet. Sandmorän Under jord med organiskt innehåll eller sand återfinns naturligt lagrad sandmorän, ibland siltig. Sandmoränens överkant påträffas först mellan ca 0,5–2,0 m u my, med en utbredning ner till ca 1,7–5,0 m u my enligt hejarsonderingar och skruvprovtagningar. Friktionsvinkeln varierar mellan ca 37–39°, och E-modulen ligger mellan ca 30–45 MPa. Lagret har en fast till mycket fast lagringstäthet.
A43: BBB.1132 | C43: Geotekniska förhållanden i berg
C44: Enligt SGU:s jorddjupskarta uppskattas jorddjupet till ca 1–3 m. Hejarsonderingar har avslutats på djup mellan ca 1,7–4,3 m u my, med stoppkod 91 (sonden kunde ej neddrivas ytterligare enligt normalt förfarande) och stoppkod 90 (sondering avslutades innan stopp erhölls). Enligt SGU:s bergartskarta utgörs underliggande berggrund av gabbroid-dioritoid.
A47: BBB.114 | C47: Hydrogeologiska förhållanden
C48: Genom området rinner diken som skall bevaras avseende funktion och omläggning av sträckning ska utföras utan att riskera grumling i diket nedströms Ekalund under hela projektets genomförande.
C50: I samband med geoteknisk undersökningen har tio grundvattenrör installerats inom området. Avläsningar vid fyra tillfällen visar att grundvattennivån generellt varierar mellan ca 0,5–2,5 m u my. Avläsningar i april och september 2023 indikerar grundvattennivåer 0,3–0,5 m högre jämfört med juni 2023. Figuren nedan visar grundvattennivåer baserade på mätningar utförda 2023-04-26, 2023-06-09, 2023-06-21, 2023-09-13 och 2023-10-17. Tidigare undersökningar redovisas med blå moln-markering. Vid skruvprovtagningar i mars och maj 2023 observerades fria vattenytor på djup mellan ca 0,3–1,6 m u my. Grundvattennivåer kan variera beroende på årstid och nederbörd.
C53: Utförda undersökningar redovisas i BBB.1 samt handling "13.8 Ställningstagande angående behov av tillstånd för vattenverksamhet Ekalund Ljungby kommun".
A55: BBB.115 | C55: Föroreningar
C56: Inom området återfinns inga kända föroreningar.
C58: Se BBB.1 för utförda undersökningar som redovisar föroreningar.
A62: BBB.117 | C62: Utförda inventeringar av skaderisker
C63: Riskanalys är ännu ej utförd för projektet. Riskanalys skall utföras av entreprenör, se BBC.17.
A65: BBB.3 | C65: Befintliga anläggningar m m
...

Sheet Handling 10.2 Mängdförteckning 
A1: #VALUE! | C1: Projektnamn | H1: Datum | I1: Instruktion: Samtliga gråa fält fylls i av anbudsgivaren. Negativ prissättning acceoteras ej, se AFB.41 i upphandlingens administrativa föreskrifter (AF).
C2: Ekalund Industriområde | H2: 2025-02-13
C3: Belysning | H3: Rev datum
H4: =IF([3]Försättsblad!D34=0," ",[3]Försättsblad!D34)
C5: Status | H5: Handling
C6: FÖRFRÅGNINGSUNDERLAG | H6: 10.2
A7: Kod | C7: Text | D7: R/O | E7: Enhet | F7: Mängd | G7: a'-pris | H7: Total anbudssumma MF10.2
H8: =SUBTOTAL(9,H9:H9763) -> 0
A10: 6 | C10: EL-TELESYSTEM
C11: För entreprenaden gäller även separat redovisad
C12: AF- del.
C14: För utförande gäller, förutom denna beskrivning nedanstående icke bifogade publikationer:
C16: EL-AMA 22 med senaste AMA-nytt
C18: Starkströmsföreskrifterna, ELSÄK-FS 2022:1, :2 och :3
C21: Elleverantörens lokala bestämmelser
C23: I förfrågningsunderlaget förtecknade handlingar
C25: EBR-standard KJ 41:21.1
C27: Elinstallationsreglerna SS 436 40 00 utgåva 4 med ändringar och tillägg
C29: Teknikområde: Väg- och gatubelysning
C31: Allmänt
C32: Entreprenaden omfattar ny belysning inom nytt exploateringsområde samt för ny cirkulationsplats inkl. tillhörande GC-vägar som byggs vid befintlig väg. Anläggning strömförsörjs med ett nytt gatubelysningsskåp och 2st slavskåp
... C50: Ny elservis anmäls till nytt gatubelysningsskåp
A54: 63 | C54: ELKRAFTSYSTEM
A56: 63.F | C56: Belysningssystem och ljussystem
C57: Belysningsanläggningens uppbyggnad framgår av följande ritningar:
C59: Ritning: E-63-1-2004 till -2027
C61: Bilaga 1: Armatur & Stolpförteckning
C63: Samt enligt mängdförteckning i denna beskrivning
C65: Frånkoppling och anslutning till befintlig anläggningsdel utförs av Ljungby Energi. | D65: - | E65: - | F65: - | G65: - | H65: -
A67: B | C67: FÖRARBETEN, HJÄLPARBETEN, SANERINGSARBETEN, FLYTTNING, DEMONTERING, RIVNING, RÖJNING M M
A69: BB | C69: FÖRARBETEN
A71: BBE | C71: UTSÄTTNINGAR
A73: BBE.6 | C73: Utsättningar för el- och teleinstallationer
C74: Stolpfundament:
C75: Utsättning av läge för stolpfundament ska utföras av entreprenören. | D75: - | E75: - | F75: - | G75: - | H75: -
C77: Kabelgrav:
C78: Utsättning av läge för kabelgrav ska utföras av entreprenören. | D78: - | E78: - | F78: - | G78: - | H78: -
A80: C | C80: TERRASSERING, PÅLNING, MARKFÖRSTÄRKNING, LAGER I MARK M M
A82: CB | C82: SCHAKT
A84: CBB | C84: JORDSCHAKT
...

Sheet 6. Prisbilaga
A4: 13.1 Anbudsformulär - Ekalunds Industriområde Dnr:2023-0285
A6: ='1. Leverantörsinformation'!A6 -> Datum 2025-04-08
A8: Prisbilaga
A10: Anbudssumma enligt Handling 10.1 samt 10.2 Mängdförteckning | E10: {='Handling 10.1 Mändförteckning M'!F8:G8+'Handling 10.2 Mängdförteckning '!H8} -> 0 | F10: 0 | G10: Summeras automatiskt från Handling 10.1 samt 10.2 Mängdförteckning.

Sheet Blad1
B2: JA | E2: JA
B3: NEJ | E3: NEJ
B4: EJ AKTUELLT
